Traceback (most recent call last):
  File "C:\Users\DELL\Anaconda3\envs\ML4ChemEng\lib\site-packages\jupyter_cache\executors\utils.py", line 56, in single_nb_execution
    record_timing=False,
  File "C:\Users\DELL\Anaconda3\envs\ML4ChemEng\lib\site-packages\nbclient\client.py", line 1204, in execute
    return NotebookClient(nb=nb, resources=resources, km=km, **kwargs).execute()
  File "C:\Users\DELL\Anaconda3\envs\ML4ChemEng\lib\site-packages\nbclient\util.py", line 84, in wrapped
    return just_run(coro(*args, **kwargs))
  File "C:\Users\DELL\Anaconda3\envs\ML4ChemEng\lib\site-packages\nbclient\util.py", line 62, in just_run
    return loop.run_until_complete(coro)
  File "C:\Users\DELL\Anaconda3\envs\ML4ChemEng\lib\asyncio\base_events.py", line 587, in run_until_complete
    return future.result()
  File "C:\Users\DELL\Anaconda3\envs\ML4ChemEng\lib\site-packages\nbclient\client.py", line 664, in async_execute
    cell, index, execution_count=self.code_cells_executed + 1
  File "C:\Users\DELL\Anaconda3\envs\ML4ChemEng\lib\site-packages\nbclient\client.py", line 965, in async_execute_cell
    await self._check_raise_for_error(cell, cell_index, exec_reply)
  File "C:\Users\DELL\Anaconda3\envs\ML4ChemEng\lib\site-packages\nbclient\client.py", line 862, in _check_raise_for_error
    raise CellExecutionError.from_cell_and_msg(cell, exec_reply_content)
nbclient.exceptions.CellExecutionError: An error occurred while executing the following cell:
------------------
Ps   = X.reshape(-1,1)
Ts   = Y.reshape(-1,1)
Hs   = np.array(Z.T).reshape(-1,1)

# -- Clean data to eliminate NaN which cannot be used to fit the LR
H_bool  = np.isnan(Hs)
P_clean = np.zeros(len(Ps)-np.count_nonzero(H_bool))
T_clean = np.zeros(len(P_clean))
H_clean = np.zeros(len(P_clean))

j = 0
for i in range(P.shape[0]):
    if H_bool[i] == False:
        P_clean[j] = Ps[i]
        T_clean[j] = Ts[i]
        H_clean[j] = Hs[i]
        j += 1
------------------

[1;31m---------------------------------------------------------------------------[0m
[1;31mNameError[0m                                 Traceback (most recent call last)
[1;32m~\AppData\Local\Temp\ipykernel_14908\4047478542.py[0m in [0;36m<module>[1;34m[0m
[0;32m     10[0m [1;33m[0m[0m
[0;32m     11[0m [0mj[0m [1;33m=[0m [1;36m0[0m[1;33m[0m[1;33m[0m[0m
[1;32m---> 12[1;33m [1;32mfor[0m [0mi[0m [1;32min[0m [0mrange[0m[1;33m([0m[0mP[0m[1;33m.[0m[0mshape[0m[1;33m[[0m[1;36m0[0m[1;33m][0m[1;33m)[0m[1;33m:[0m[1;33m[0m[1;33m[0m[0m
[0m[0;32m     13[0m     [1;32mif[0m [0mH_bool[0m[1;33m[[0m[0mi[0m[1;33m][0m [1;33m==[0m [1;32mFalse[0m[1;33m:[0m[1;33m[0m[1;33m[0m[0m
[0;32m     14[0m         [0mP_clean[0m[1;33m[[0m[0mj[0m[1;33m][0m [1;33m=[0m [0mPs[0m[1;33m[[0m[0mi[0m[1;33m][0m[1;33m[0m[1;33m[0m[0m

[1;31mNameError[0m: name 'P' is not defined
NameError: name 'P' is not defined

